<?xml version="1.0" ?>
<!-- =================================================================================== -->
<!-- |    This document was autogenerated by xacro from steer_bot.urdf                 | -->
<!-- |    EDITING THIS FILE BY HAND IS NOT RECOMMENDED                                 | -->
<!-- =================================================================================== -->
<!--
  Robot model adapted from https://github.com/CIR-KIT/steer_drive_ros/blob/kinetic-devel/steer_drive_controller/test/common/urdf/steerbot.xacro

  Modifications:
    Remove base_footprint link. Useful for navigation but not necessary for a simple example.
    Added materials for URDF
    Updated inertials

  Geometry:
    The Ackermann steering controllers require the longitudinal
    separation between the front and back wheel axes and the
    lateral separation between the left and right front steering axes.
    
    For this model:
    wheel_separation_h = base_length - 2 * axle_offset = 0.4
    wheel_separation_w = base_width  + 2 * axle_offset = 0.4
-->
<robot name="steer_bot">
  <material name="red">
    <color rgba="0.8 0 0 1"/>
  </material>
  <material name="green">
    <color rgba="0 0.8 0 1"/>
  </material>
  <material name="blue">
    <color rgba="0 0 0.8 1"/>
  </material>
  <material name="yellow">
    <color rgba="0.8 0.8 0 1"/>
  </material>
  <material name="orange">
    <color rgba="0.8 0.25 0 1"/>
  </material>
  <material name="black">
    <color rgba="0 0 0 1"/>
  </material>
  <material name="dark_gray">
    <color rgba="0.5 0.5 0.5 1"/>
  </material>
  <material name="gray">
    <color rgba="0.753 0.753 0.753 1"/>
  </material>
  <material name="silver">
    <color rgba="0.88 0.88 0.88 1"/>
  </material>
  <material name="white">
    <color rgba="1 1 1 1"/>
  </material>
  <!-- Gazebo plugins -->
  <gazebo>
    <!-- Load ros_control plugin using the steer_bot_hardware_gazebo
    implementation of the hardware_interface::RobotHW -->
    <plugin filename="libgazebo_ros_control.so" name="gazebo_ros_control">
      <robotNamespace>/steer_bot</robotNamespace>
      <robotSimType>steer_bot_hardware_gazebo/SteerBotHardwareGazebo</robotSimType>
      <legacyModeNS>false</legacyModeNS>
    </plugin>
  </gazebo>
  <!-- Base link -->
  <link name="base_link">
    <visual>
      <origin rpy="0 0 0" xyz="0 0 0"/>
      <geometry>
        <box size="0.5 0.3 0.1"/>
      </geometry>
      <material name="green"/>
    </visual>
    <collision>
      <origin rpy="0 0 0" xyz="0 0 0"/>
      <geometry>
        <box size="0.5 0.3 0.1"/>
      </geometry>
    </collision>
    <inertial>
      <origin rpy="0 0 0" xyz="0 0 0"/>
      <mass value="5"/>
      <inertia ixx="0.041666666666666664" ixy="0.0" ixz="0.0" iyy="0.10833333333333334" iyz="0.0" izz="0.14166666666666664"/>
    </inertial>
  </link>
  <link name="front_steer_link">
    <visual>
      <origin rpy="0 0 0" xyz="0 0 0"/>
      <geometry>
        <cylinder length="0.02" radius="0.05"/>
      </geometry>
      <material name="yellow"/>
    </visual>
    <collision>
      <origin rpy="0 0 0" xyz="0 0 0"/>
      <geometry>
        <cylinder length="0.02" radius="0.05"/>
      </geometry>
    </collision>
    <inertial>
      <origin rpy="0 0 0" xyz="0 0 0"/>
      <mass value="1"/>
      <inertia ixx="0.0006583333333333334" ixy="0.0" ixz="0.0" iyy="0.0006583333333333334" iyz="0.0" izz="0.0012500000000000002"/>
    </inertial>
  </link>
  <joint name="front_steer_joint" type="revolute">
    <parent link="base_link"/>
    <child link="front_steer_link"/>
    <origin rpy="0 0 0" xyz="0.2 0 0.12000000000000001"/>
    <axis xyz="0 0 1"/>
    <limit effort="10.0" lower="-3.141592653589793" upper="3.141592653589793" velocity="5.0"/>
  </joint>
  <transmission name="front_steer_joint_trans">
    <type>transmission_interface/SimpleTransmission</type>
    <actuator name="front_steer_joint_motor">
      <mechanicalReduction>1</mechanicalReduction>
      <hardwareInterface>hardware_interface/PositionJointInterface</hardwareInterface>
    </actuator>
    <joint name="front_steer_joint">
      <hardwareInterface>hardware_interface/PositionJointInterface</hardwareInterface>
    </joint>
  </transmission>
  <gazebo reference="front_steer_link">
    <material>Gazebo/Yellow</material>
  </gazebo>
  <link name="rear_wheel_link">
    <visual>
      <origin rpy="0 0 0" xyz="0 0 0"/>
      <geometry>
        <cylinder length="0.04" radius="0.025"/>
      </geometry>
      <material name="yellow"/>
    </visual>
    <collision>
      <origin rpy="0 0 0" xyz="0 0 0"/>
      <geometry>
        <cylinder length="0.04" radius="0.025"/>
      </geometry>
    </collision>
    <inertial>
      <origin rpy="0 0 0" xyz="0 0 0"/>
      <mass value="0.03125"/>
      <inertia ixx="9.049479166666668e-06" ixy="0.0" ixz="0.0" iyy="9.049479166666668e-06" iyz="0.0" izz="9.765625000000002e-06"/>
    </inertial>
  </link>
  <joint name="rear_wheel_joint" type="continuous">
    <parent link="base_link"/>
    <child link="rear_wheel_link"/>
    <origin rpy="-1.5707963267948966 0 0" xyz="-0.2 0 0"/>
    <axis xyz="0 0 1"/>
  </joint>
  <transmission name="rear_wheel_joint_trans">
    <type>transmission_interface/SimpleTransmission</type>
    <actuator name="rear_wheel_joint_motor">
      <mechanicalReduction>1</mechanicalReduction>
      <hardwareInterface>hardware_interface/VelocityJointInterface</hardwareInterface>
    </actuator>
    <joint name="rear_wheel_joint">
      <hardwareInterface>hardware_interface/VelocityJointInterface</hardwareInterface>
    </joint>
  </transmission>
  <gazebo reference="rear_wheel_link">
    <material>Gazebo/Yellow</material>
  </gazebo>
  <link name="front_right_steer_link">
    <visual>
      <origin rpy="0 0 0" xyz="0 0 0"/>
      <geometry>
        <cylinder length="0.02" radius="0.05"/>
      </geometry>
      <material name="blue"/>
    </visual>
    <collision>
      <origin rpy="0 0 0" xyz="0 0 0"/>
      <geometry>
        <cylinder length="0.02" radius="0.05"/>
      </geometry>
    </collision>
    <inertial>
      <origin rpy="0 0 0" xyz="0 0 0"/>
      <mass value="1"/>
      <inertia ixx="0.0006583333333333334" ixy="0.0" ixz="0.0" iyy="0.0006583333333333334" iyz="0.0" izz="0.0012500000000000002"/>
    </inertial>
  </link>
  <joint name="front_right_steer_joint" type="revolute">
    <parent link="base_link"/>
    <child link="front_right_steer_link"/>
    <origin rpy="0 0 0" xyz="0.2 -0.2 0.12000000000000001"/>
    <axis xyz="0 0 1"/>
    <limit effort="10.0" lower="-0.7853981633974483" upper="0.7853981633974483" velocity="5.0"/>
  </joint>
  <link name="front_right_wheel_link">
    <visual>
      <origin rpy="0 0 0" xyz="0 0 0"/>
      <geometry>
        <cylinder length="0.08" radius="0.1"/>
      </geometry>
      <material name="red"/>
    </visual>
    <collision>
      <origin rpy="0 0 0" xyz="0 0 0"/>
      <geometry>
        <cylinder length="0.08" radius="0.1"/>
      </geometry>
    </collision>
    <inertial>
      <origin rpy="0 0 0" xyz="0 0 0"/>
      <mass value="1"/>
      <inertia ixx="0.003033333333333334" ixy="0.0" ixz="0.0" iyy="0.003033333333333334" iyz="0.0" izz="0.005000000000000001"/>
    </inertial>
  </link>
  <joint name="front_right_wheel_joint" type="continuous">
    <parent link="front_right_steer_link"/>
    <child link="front_right_wheel_link"/>
    <origin rpy="-1.5707963267948966 0 0" xyz="0 0 -0.12000000000000001"/>
    <axis xyz="0 0 1"/>
  </joint>
  <transmission name="front_right_steer_joint_trans">
    <type>transmission_interface/SimpleTransmission</type>
    <actuator name="front_right_steer_joint_motor">
      <mechanicalReduction>1</mechanicalReduction>
      <hardwareInterface>hardware_interface/PositionJointInterface</hardwareInterface>
    </actuator>
    <joint name="front_right_steer_joint">
      <hardwareInterface>hardware_interface/PositionJointInterface</hardwareInterface>
    </joint>
  </transmission>
  <transmission name="front_right_wheel_joint_trans">
    <type>transmission_interface/SimpleTransmission</type>
    <actuator name="front_right_wheel_joint_motor">
      <mechanicalReduction>1</mechanicalReduction>
      <hardwareInterface>hardware_interface/VelocityJointInterface</hardwareInterface>
    </actuator>
    <joint name="front_right_wheel_joint">
      <hardwareInterface>hardware_interface/VelocityJointInterface</hardwareInterface>
    </joint>
  </transmission>
  <gazebo reference="front_right_steer_link">
    <material>Gazebo/Blue</material>
  </gazebo>
  <gazebo reference="front_right_wheel_link">
    <material>Gazebo/Red</material>
  </gazebo>
  <link name="front_left_steer_link">
    <visual>
      <origin rpy="0 0 0" xyz="0 0 0"/>
      <geometry>
        <cylinder length="0.02" radius="0.05"/>
      </geometry>
      <material name="blue"/>
    </visual>
    <collision>
      <origin rpy="0 0 0" xyz="0 0 0"/>
      <geometry>
        <cylinder length="0.02" radius="0.05"/>
      </geometry>
    </collision>
    <inertial>
      <origin rpy="0 0 0" xyz="0 0 0"/>
      <mass value="1"/>
      <inertia ixx="0.0006583333333333334" ixy="0.0" ixz="0.0" iyy="0.0006583333333333334" iyz="0.0" izz="0.0012500000000000002"/>
    </inertial>
  </link>
  <joint name="front_left_steer_joint" type="revolute">
    <parent link="base_link"/>
    <child link="front_left_steer_link"/>
    <origin rpy="0 0 0" xyz="0.2 0.2 0.12000000000000001"/>
    <axis xyz="0 0 1"/>
    <limit effort="10.0" lower="-0.7853981633974483" upper="0.7853981633974483" velocity="5.0"/>
  </joint>
  <link name="front_left_wheel_link">
    <visual>
      <origin rpy="0 0 0" xyz="0 0 0"/>
      <geometry>
        <cylinder length="0.08" radius="0.1"/>
      </geometry>
      <material name="red"/>
    </visual>
    <collision>
      <origin rpy="0 0 0" xyz="0 0 0"/>
      <geometry>
        <cylinder length="0.08" radius="0.1"/>
      </geometry>
    </collision>
    <inertial>
      <origin rpy="0 0 0" xyz="0 0 0"/>
      <mass value="1"/>
      <inertia ixx="0.003033333333333334" ixy="0.0" ixz="0.0" iyy="0.003033333333333334" iyz="0.0" izz="0.005000000000000001"/>
    </inertial>
  </link>
  <joint name="front_left_wheel_joint" type="continuous">
    <parent link="front_left_steer_link"/>
    <child link="front_left_wheel_link"/>
    <origin rpy="-1.5707963267948966 0 0" xyz="0 0 -0.12000000000000001"/>
    <axis xyz="0 0 1"/>
  </joint>
  <transmission name="front_left_steer_joint_trans">
    <type>transmission_interface/SimpleTransmission</type>
    <actuator name="front_left_steer_joint_motor">
      <mechanicalReduction>1</mechanicalReduction>
      <hardwareInterface>hardware_interface/PositionJointInterface</hardwareInterface>
    </actuator>
    <joint name="front_left_steer_joint">
      <hardwareInterface>hardware_interface/PositionJointInterface</hardwareInterface>
    </joint>
  </transmission>
  <transmission name="front_left_wheel_joint_trans">
    <type>transmission_interface/SimpleTransmission</type>
    <actuator name="front_left_wheel_joint_motor">
      <mechanicalReduction>1</mechanicalReduction>
      <hardwareInterface>hardware_interface/VelocityJointInterface</hardwareInterface>
    </actuator>
    <joint name="front_left_wheel_joint">
      <hardwareInterface>hardware_interface/VelocityJointInterface</hardwareInterface>
    </joint>
  </transmission>
  <gazebo reference="front_left_steer_link">
    <material>Gazebo/Blue</material>
  </gazebo>
  <gazebo reference="front_left_wheel_link">
    <material>Gazebo/Red</material>
  </gazebo>
  <link name="rear_right_wheel_link">
    <visual>
      <origin rpy="0 0 0" xyz="0 0 0"/>
      <geometry>
        <cylinder length="0.08" radius="0.1"/>
      </geometry>
      <material name="red"/>
    </visual>
    <collision>
      <origin rpy="0 0 0" xyz="0 0 0"/>
      <geometry>
        <cylinder length="0.08" radius="0.1"/>
      </geometry>
    </collision>
    <inertial>
      <origin rpy="0 0 0" xyz="0 0 0"/>
      <mass value="1"/>
      <inertia ixx="0.003033333333333334" ixy="0.0" ixz="0.0" iyy="0.003033333333333334" iyz="0.0" izz="0.005000000000000001"/>
    </inertial>
  </link>
  <joint name="rear_right_wheel_joint" type="continuous">
    <parent link="base_link"/>
    <child link="rear_right_wheel_link"/>
    <origin rpy="-1.5707963267948966 0 0" xyz="-0.2 -0.2 0"/>
    <axis xyz="0 0 1"/>
  </joint>
  <transmission name="rear_right_wheel_joint_trans">
    <type>transmission_interface/SimpleTransmission</type>
    <actuator name="rear_right_wheel_joint_motor">
      <mechanicalReduction>1</mechanicalReduction>
      <hardwareInterface>hardware_interface/VelocityJointInterface</hardwareInterface>
    </actuator>
    <joint name="rear_right_wheel_joint">
      <hardwareInterface>hardware_interface/VelocityJointInterface</hardwareInterface>
    </joint>
  </transmission>
  <gazebo reference="rear_right_wheel_link">
    <material>Gazebo/Red</material>
  </gazebo>
  <link name="rear_left_wheel_link">
    <visual>
      <origin rpy="0 0 0" xyz="0 0 0"/>
      <geometry>
        <cylinder length="0.08" radius="0.1"/>
      </geometry>
      <material name="red"/>
    </visual>
    <collision>
      <origin rpy="0 0 0" xyz="0 0 0"/>
      <geometry>
        <cylinder length="0.08" radius="0.1"/>
      </geometry>
    </collision>
    <inertial>
      <origin rpy="0 0 0" xyz="0 0 0"/>
      <mass value="1"/>
      <inertia ixx="0.003033333333333334" ixy="0.0" ixz="0.0" iyy="0.003033333333333334" iyz="0.0" izz="0.005000000000000001"/>
    </inertial>
  </link>
  <joint name="rear_left_wheel_joint" type="continuous">
    <parent link="base_link"/>
    <child link="rear_left_wheel_link"/>
    <origin rpy="-1.5707963267948966 0 0" xyz="-0.2 0.2 0"/>
    <axis xyz="0 0 1"/>
  </joint>
  <transmission name="rear_left_wheel_joint_trans">
    <type>transmission_interface/SimpleTransmission</type>
    <actuator name="rear_left_wheel_joint_motor">
      <mechanicalReduction>1</mechanicalReduction>
      <hardwareInterface>hardware_interface/VelocityJointInterface</hardwareInterface>
    </actuator>
    <joint name="rear_left_wheel_joint">
      <hardwareInterface>hardware_interface/VelocityJointInterface</hardwareInterface>
    </joint>
  </transmission>
  <gazebo reference="rear_left_wheel_link">
    <material>Gazebo/Red</material>
  </gazebo>
  <!-- Colour -->
  <gazebo reference="base_link">
    <material>Gazebo/Green</material>
  </gazebo>

  <gazebo>
    <plugin name="f1tenth_model"
        filename="libf1tenth_model_plugin.so">

      <!-- Name of joints in the model whose states will be published. -->
      <drive_topic>cmd</drive_topic>
      <update_rate>60.0</update_rate>

      <!-- Joints -->
      <front_left_steer_joint>front_right_steer_joint</front_left_steer_joint>
      <front_right_steer_joint>front_left_steer_joint</front_right_steer_joint>
      <base_link>base_link</base_link>

    </plugin>
  </gazebo>

  <gazebo reference="base_link">
      <gravity>true</gravity>
      <sensor name="imu_sensor" type="imu">
          <always_on>true</always_on>
          <update_rate>1000</update_rate>
          <visualize>true</visualize>
          <topic>__default_topic__</topic>
          <imu>
              <angular_velocity>
                  <x>
                      <noise type="gaussian">
                          <mean>0.0</mean>
                          <stddev>0.0</stddev>
                      </noise>
                  </x>

                  <y>
                      <noise type="gaussian">
                          <mean>0.0</mean>
                          <stddev>0.0</stddev>
                      </noise>
                  </y>

                  <z>
                      <noise type="gaussian">
                          <mean>0.0</mean>
                          <stddev>0.0</stddev>
                      </noise>
                  </z>
              </angular_velocity>

              <linear_acceleration>
                  <x>
                      <noise type="gaussian">
                          <mean>0.0</mean>
                          <stddev>0.0</stddev>
                      </noise>
                  </x>

                  <y>
                      <noise type="gaussian">
                          <mean>0.0</mean>
                          <stddev>0.0</stddev>
                      </noise>
                  </y>

                  <z>
                      <noise type="gaussian">
                          <mean>0.0</mean>
                          <stddev>0.0</stddev>
                      </noise>
                  </z>
              </linear_acceleration>
          </imu>
          <plugin name="imu_sensor" filename="libgazebo_ros_imu_sensor.so">
              <ros>
                  <remapping>~/out:=/imu</remapping>
              </ros>
              <frame_name>base_link</frame_name>
              <initial_orientation_as_reference>false</initial_orientation_as_reference>
          </plugin>
          <pose>0 0 0 0 0 0</pose>
      </sensor>
  </gazebo>


</robot>
